[2024-05-11T20:15:02.112+0000] {taskinstance.py:1979} INFO - Dependencies all met for dep_context=non-requeueable deps ti=<TaskInstance: live_ademe.check_environment_setup scheduled__2024-05-11T20:10:00+00:00 [queued]>
[2024-05-11T20:15:02.120+0000] {taskinstance.py:1979} INFO - Dependencies all met for dep_context=requeueable deps ti=<TaskInstance: live_ademe.check_environment_setup scheduled__2024-05-11T20:10:00+00:00 [queued]>
[2024-05-11T20:15:02.120+0000] {taskinstance.py:2193} INFO - Starting attempt 1 of 2
[2024-05-11T20:15:02.136+0000] {taskinstance.py:2217} INFO - Executing <Task(PythonOperator): check_environment_setup> on 2024-05-11 20:10:00+00:00
[2024-05-11T20:15:02.147+0000] {standard_task_runner.py:60} INFO - Started process 593 to run task
[2024-05-11T20:15:02.153+0000] {standard_task_runner.py:87} INFO - Running: ['***', 'tasks', 'run', 'live_ademe', 'check_environment_setup', 'scheduled__2024-05-11T20:10:00+00:00', '--job-id', '409', '--raw', '--subdir', 'DAGS_FOLDER/ademe_dag.py', '--cfg-path', '/tmp/tmpc_egf6i_']
[2024-05-11T20:15:02.156+0000] {standard_task_runner.py:88} INFO - Job 409: Subtask check_environment_setup
[2024-05-11T20:15:02.214+0000] {task_command.py:423} INFO - Running <TaskInstance: live_ademe.check_environment_setup scheduled__2024-05-11T20:10:00+00:00 [running]> on host ced256f15635
[2024-05-11T20:15:02.295+0000] {taskinstance.py:2513} INFO - Exporting env vars: AIRFLOW_CTX_DAG_EMAIL='***@example.com' AIRFLOW_CTX_DAG_OWNER='***' AIRFLOW_CTX_DAG_ID='live_ademe' AIRFLOW_CTX_TASK_ID='check_environment_setup' AIRFLOW_CTX_EXECUTION_DATE='2024-05-11T20:10:00+00:00' AIRFLOW_CTX_TRY_NUMBER='1' AIRFLOW_CTX_DAG_RUN_ID='scheduled__2024-05-11T20:10:00+00:00'
[2024-05-11T20:15:02.297+0000] {ademe_dag.py:83} INFO - ----------------------------------------
[2024-05-11T20:15:02.297+0000] {ademe_dag.py:84} INFO - [info logger] cwd: /opt/***
[2024-05-11T20:15:02.297+0000] {taskinstance.py:2731} ERROR - Task failed with exception
Traceback (most recent call last):
  File "/home/airflow/.local/lib/python3.8/site-packages/airflow/models/taskinstance.py", line 444, in _execute_task
    result = _execute_callable(context=context, **execute_callable_kwargs)
  File "/home/airflow/.local/lib/python3.8/site-packages/airflow/models/taskinstance.py", line 414, in _execute_callable
    return execute_callable(context=context, **execute_callable_kwargs)
  File "/home/airflow/.local/lib/python3.8/site-packages/airflow/operators/python.py", line 200, in execute
    return_value = self.execute_callable()
  File "/home/airflow/.local/lib/python3.8/site-packages/airflow/operators/python.py", line 217, in execute_callable
    return self.python_callable(*self.op_args, **self.op_kwargs)
  File "/opt/airflow/dags/ademe_dag.py", line 85, in check_environment_setup
    assert os.path.isfile(URL_FILE)
AssertionError
[2024-05-11T20:15:02.305+0000] {taskinstance.py:1149} INFO - Marking task as UP_FOR_RETRY. dag_id=live_ademe, task_id=check_environment_setup, execution_date=20240511T201000, start_date=20240511T201502, end_date=20240511T201502
[2024-05-11T20:15:02.317+0000] {standard_task_runner.py:107} ERROR - Failed to execute job 409 for task check_environment_setup (; 593)
[2024-05-11T20:15:02.365+0000] {local_task_job_runner.py:234} INFO - Task exited with return code 1
[2024-05-11T20:15:02.393+0000] {taskinstance.py:3312} INFO - 0 downstream tasks scheduled from follow-on schedule check
