[2024-04-11T13:33:12.865+0000] {taskinstance.py:1979} INFO - Dependencies all met for dep_context=non-requeueable deps ti=<TaskInstance: live_ademe.check_environment_setup scheduled__2024-04-11T13:15:00+00:00 [queued]>
[2024-04-11T13:33:12.874+0000] {taskinstance.py:1979} INFO - Dependencies all met for dep_context=requeueable deps ti=<TaskInstance: live_ademe.check_environment_setup scheduled__2024-04-11T13:15:00+00:00 [queued]>
[2024-04-11T13:33:12.874+0000] {taskinstance.py:2193} INFO - Starting attempt 3 of 4
[2024-04-11T13:33:12.911+0000] {taskinstance.py:2217} INFO - Executing <Task(PythonOperator): check_environment_setup> on 2024-04-11 13:15:00+00:00
[2024-04-11T13:33:12.918+0000] {standard_task_runner.py:60} INFO - Started process 2866 to run task
[2024-04-11T13:33:12.924+0000] {standard_task_runner.py:87} INFO - Running: ['***', 'tasks', 'run', 'live_ademe', 'check_environment_setup', 'scheduled__2024-04-11T13:15:00+00:00', '--job-id', '12', '--raw', '--subdir', 'DAGS_FOLDER/ademe_dag.py', '--cfg-path', '/tmp/tmp5km7emx1']
[2024-04-11T13:33:12.928+0000] {standard_task_runner.py:88} INFO - Job 12: Subtask check_environment_setup
[2024-04-11T13:33:13.023+0000] {task_command.py:423} INFO - Running <TaskInstance: live_ademe.check_environment_setup scheduled__2024-04-11T13:15:00+00:00 [running]> on host ced256f15635
[2024-04-11T13:33:13.830+0000] {taskinstance.py:2513} INFO - Exporting env vars: AIRFLOW_CTX_DAG_EMAIL='***@example.com' AIRFLOW_CTX_DAG_OWNER='***' AIRFLOW_CTX_DAG_ID='live_ademe' AIRFLOW_CTX_TASK_ID='check_environment_setup' AIRFLOW_CTX_EXECUTION_DATE='2024-04-11T13:15:00+00:00' AIRFLOW_CTX_TRY_NUMBER='3' AIRFLOW_CTX_DAG_RUN_ID='scheduled__2024-04-11T13:15:00+00:00'
[2024-04-11T13:33:13.832+0000] {ademe_dag.py:81} INFO - ----------------------------------------
[2024-04-11T13:33:13.834+0000] {ademe_dag.py:82} INFO - [info logger] cwd: /opt/***
[2024-04-11T13:33:13.834+0000] {taskinstance.py:2731} ERROR - Task failed with exception
Traceback (most recent call last):
  File "/home/airflow/.local/lib/python3.8/site-packages/airflow/models/taskinstance.py", line 444, in _execute_task
    result = _execute_callable(context=context, **execute_callable_kwargs)
  File "/home/airflow/.local/lib/python3.8/site-packages/airflow/models/taskinstance.py", line 414, in _execute_callable
    return execute_callable(context=context, **execute_callable_kwargs)
  File "/home/airflow/.local/lib/python3.8/site-packages/airflow/operators/python.py", line 200, in execute
    return_value = self.execute_callable()
  File "/home/airflow/.local/lib/python3.8/site-packages/airflow/operators/python.py", line 217, in execute_callable
    return self.python_callable(*self.op_args, **self.op_kwargs)
  File "/opt/airflow/dags/ademe_dag.py", line 83, in check_environment_setup
    assert os.path.isfile(URL_FILE)
AssertionError
[2024-04-11T13:33:13.842+0000] {taskinstance.py:1149} INFO - Marking task as UP_FOR_RETRY. dag_id=live_ademe, task_id=check_environment_setup, execution_date=20240411T131500, start_date=20240411T133312, end_date=20240411T133313
[2024-04-11T13:33:13.856+0000] {standard_task_runner.py:107} ERROR - Failed to execute job 12 for task check_environment_setup (; 2866)
[2024-04-11T13:33:13.900+0000] {local_task_job_runner.py:234} INFO - Task exited with return code 1
[2024-04-11T13:33:13.927+0000] {taskinstance.py:3312} INFO - 0 downstream tasks scheduled from follow-on schedule check
