[2024-04-11T14:45:02.999+0000] {taskinstance.py:1979} INFO - Dependencies all met for dep_context=non-requeueable deps ti=<TaskInstance: live_ademe.check_environment_setup scheduled__2024-04-11T14:40:00+00:00 [queued]>
[2024-04-11T14:45:03.022+0000] {taskinstance.py:1979} INFO - Dependencies all met for dep_context=requeueable deps ti=<TaskInstance: live_ademe.check_environment_setup scheduled__2024-04-11T14:40:00+00:00 [queued]>
[2024-04-11T14:45:03.023+0000] {taskinstance.py:2193} INFO - Starting attempt 1 of 2
[2024-04-11T14:45:03.667+0000] {taskinstance.py:2217} INFO - Executing <Task(PythonOperator): check_environment_setup> on 2024-04-11 14:40:00+00:00
[2024-04-11T14:45:03.684+0000] {standard_task_runner.py:60} INFO - Started process 4019 to run task
[2024-04-11T14:45:03.715+0000] {standard_task_runner.py:87} INFO - Running: ['***', 'tasks', 'run', 'live_ademe', 'check_environment_setup', 'scheduled__2024-04-11T14:40:00+00:00', '--job-id', '44', '--raw', '--subdir', 'DAGS_FOLDER/ademe_dag.py', '--cfg-path', '/tmp/tmpxvzhqos7']
[2024-04-11T14:45:03.733+0000] {standard_task_runner.py:88} INFO - Job 44: Subtask check_environment_setup
[2024-04-11T14:45:03.883+0000] {task_command.py:423} INFO - Running <TaskInstance: live_ademe.check_environment_setup scheduled__2024-04-11T14:40:00+00:00 [running]> on host ced256f15635
[2024-04-11T14:45:04.096+0000] {taskinstance.py:2513} INFO - Exporting env vars: AIRFLOW_CTX_DAG_EMAIL='***@example.com' AIRFLOW_CTX_DAG_OWNER='***' AIRFLOW_CTX_DAG_ID='live_ademe' AIRFLOW_CTX_TASK_ID='check_environment_setup' AIRFLOW_CTX_EXECUTION_DATE='2024-04-11T14:40:00+00:00' AIRFLOW_CTX_TRY_NUMBER='1' AIRFLOW_CTX_DAG_RUN_ID='scheduled__2024-04-11T14:40:00+00:00'
[2024-04-11T14:45:04.098+0000] {ademe_dag.py:83} INFO - ----------------------------------------
[2024-04-11T14:45:04.098+0000] {ademe_dag.py:84} INFO - [info logger] cwd: /opt/***
[2024-04-11T14:45:04.099+0000] {taskinstance.py:2731} ERROR - Task failed with exception
Traceback (most recent call last):
  File "/home/airflow/.local/lib/python3.8/site-packages/airflow/models/taskinstance.py", line 444, in _execute_task
    result = _execute_callable(context=context, **execute_callable_kwargs)
  File "/home/airflow/.local/lib/python3.8/site-packages/airflow/models/taskinstance.py", line 414, in _execute_callable
    return execute_callable(context=context, **execute_callable_kwargs)
  File "/home/airflow/.local/lib/python3.8/site-packages/airflow/operators/python.py", line 200, in execute
    return_value = self.execute_callable()
  File "/home/airflow/.local/lib/python3.8/site-packages/airflow/operators/python.py", line 217, in execute_callable
    return self.python_callable(*self.op_args, **self.op_kwargs)
  File "/opt/airflow/dags/ademe_dag.py", line 85, in check_environment_setup
    assert os.path.isfile(URL_FILE)
AssertionError
[2024-04-11T14:45:04.110+0000] {taskinstance.py:1149} INFO - Marking task as UP_FOR_RETRY. dag_id=live_ademe, task_id=check_environment_setup, execution_date=20240411T144000, start_date=20240411T144503, end_date=20240411T144504
[2024-04-11T14:45:04.335+0000] {standard_task_runner.py:107} ERROR - Failed to execute job 44 for task check_environment_setup (; 4019)
[2024-04-11T14:45:04.387+0000] {local_task_job_runner.py:234} INFO - Task exited with return code 1
[2024-04-11T14:45:04.428+0000] {taskinstance.py:3312} INFO - 0 downstream tasks scheduled from follow-on schedule check
