[2024-05-11T16:15:03.348+0000] {taskinstance.py:1979} INFO - Dependencies all met for dep_context=non-requeueable deps ti=<TaskInstance: live_ademe.check_environment_setup scheduled__2024-05-11T16:05:00+00:00 [queued]>
[2024-05-11T16:15:03.355+0000] {taskinstance.py:1979} INFO - Dependencies all met for dep_context=requeueable deps ti=<TaskInstance: live_ademe.check_environment_setup scheduled__2024-05-11T16:05:00+00:00 [queued]>
[2024-05-11T16:15:03.355+0000] {taskinstance.py:2193} INFO - Starting attempt 2 of 2
[2024-05-11T16:15:03.368+0000] {taskinstance.py:2217} INFO - Executing <Task(PythonOperator): check_environment_setup> on 2024-05-11 16:05:00+00:00
[2024-05-11T16:15:03.375+0000] {standard_task_runner.py:60} INFO - Started process 1470 to run task
[2024-05-11T16:15:03.380+0000] {standard_task_runner.py:87} INFO - Running: ['***', 'tasks', 'run', 'live_ademe', 'check_environment_setup', 'scheduled__2024-05-11T16:05:00+00:00', '--job-id', '152', '--raw', '--subdir', 'DAGS_FOLDER/ademe_dag.py', '--cfg-path', '/tmp/tmpulm3vspv']
[2024-05-11T16:15:03.383+0000] {standard_task_runner.py:88} INFO - Job 152: Subtask check_environment_setup
[2024-05-11T16:15:03.438+0000] {task_command.py:423} INFO - Running <TaskInstance: live_ademe.check_environment_setup scheduled__2024-05-11T16:05:00+00:00 [running]> on host ced256f15635
[2024-05-11T16:15:03.511+0000] {taskinstance.py:2513} INFO - Exporting env vars: AIRFLOW_CTX_DAG_EMAIL='***@example.com' AIRFLOW_CTX_DAG_OWNER='***' AIRFLOW_CTX_DAG_ID='live_ademe' AIRFLOW_CTX_TASK_ID='check_environment_setup' AIRFLOW_CTX_EXECUTION_DATE='2024-05-11T16:05:00+00:00' AIRFLOW_CTX_TRY_NUMBER='2' AIRFLOW_CTX_DAG_RUN_ID='scheduled__2024-05-11T16:05:00+00:00'
[2024-05-11T16:15:03.513+0000] {ademe_dag.py:83} INFO - ----------------------------------------
[2024-05-11T16:15:03.513+0000] {ademe_dag.py:84} INFO - [info logger] cwd: /opt/***
[2024-05-11T16:15:03.514+0000] {taskinstance.py:2731} ERROR - Task failed with exception
Traceback (most recent call last):
  File "/home/airflow/.local/lib/python3.8/site-packages/airflow/models/taskinstance.py", line 444, in _execute_task
    result = _execute_callable(context=context, **execute_callable_kwargs)
  File "/home/airflow/.local/lib/python3.8/site-packages/airflow/models/taskinstance.py", line 414, in _execute_callable
    return execute_callable(context=context, **execute_callable_kwargs)
  File "/home/airflow/.local/lib/python3.8/site-packages/airflow/operators/python.py", line 200, in execute
    return_value = self.execute_callable()
  File "/home/airflow/.local/lib/python3.8/site-packages/airflow/operators/python.py", line 217, in execute_callable
    return self.python_callable(*self.op_args, **self.op_kwargs)
  File "/opt/airflow/dags/ademe_dag.py", line 85, in check_environment_setup
    assert os.path.isfile(URL_FILE)
AssertionError
[2024-05-11T16:15:03.520+0000] {taskinstance.py:1149} INFO - Marking task as FAILED. dag_id=live_ademe, task_id=check_environment_setup, execution_date=20240511T160500, start_date=20240511T161503, end_date=20240511T161503
[2024-05-11T16:15:03.536+0000] {standard_task_runner.py:107} ERROR - Failed to execute job 152 for task check_environment_setup (; 1470)
[2024-05-11T16:15:03.552+0000] {local_task_job_runner.py:234} INFO - Task exited with return code 1
[2024-05-11T16:15:03.577+0000] {taskinstance.py:3312} INFO - 0 downstream tasks scheduled from follow-on schedule check
